Workbook

Sheet 1-Balance Sheet
B2: WaveCare Forecast
B3: Pro-Forma Balance Sheet
C4: 2027 | D4: 2028 | E4: 2029 | F4: 2030 | G4: 2031
C5: Year 1 | D5: Year 2 | E5: Year 3 | F5: Year 4 | G5: Year 5 | I5: Note
B6: Assets | I6: Item | J6: Symbol | K6: Value | L6: Explanation
B7: Current assets: | I7: Days Sales Outstanding | J7: DSO | K7: 30 days | L7: Nursing homes pay within 30 days
B8: Cash | C8: ='3-Cash Flow Statement'!C23 -> 360897.88 | D8: ='3-Cash Flow Statement'!D23 -> 398044.73 | E8: ='3-Cash Flow Statement'!E23 -> 833935.13 | F8: ='3-Cash Flow Statement'!F23 -> 1735105.2 | G8: ='3-Cash Flow Statement'!G23 -> 3303258.1 | I8: Days Payable Outstanding | J8: DPO | K8: 30 days | L8: We pay suppliers within 30 days
B9: Accounts Receivable | C9: =('2-Income Statement'!D48*30)/365 -> 12093.534 | D9: =('2-Income Statement'!E48*30)/365 -> 36971.753 | E9: =('2-Income Statement'!F48*30)/365 -> 93906.266 | F9: =('2-Income Statement'!G48*30)/365 -> 158080.75 | G9: =('2-Income Statement'!H48*30)/365 -> 239747.89 | I9: Inventory Days | J9: InvDays | K9: 15 days | L9: We hold 15 days of COGS as finished goods
B10: Inventory | C10: =('2-Income Statement'!D49*15)/365 -> 1475.7308 | D10: =('2-Income Statement'!E49*15)/365 -> 3347.8021 | E10: =('2-Income Statement'!F49*15)/365 -> 5044.5688 | F10: =('2-Income Statement'!G49*15)/365 -> 7201.7858 | G10: =('2-Income Statement'!H49*15)/365 -> 9799.4805 | I10: Accrued Expenses Days | J10: AccDays | K10: 15 days | L10: Salaries and other OpEx are paid semi‑monthly
B11: Total current assets | C11: =SUM(C8:C10) -> 374467.15 | D11: =SUM(D8:D10) -> 438364.29 | E11: =SUM(E8:E10) -> 932885.96 | F11: =SUM(F8:F10) -> 1900387.8 | G11: =SUM(G8:G10) -> 3552805.4 | I11: Depreciation (annual) | J11: – | K11: $0 | L11: Assume office equipment is expensed, no large fixed assets yet
B12: Fixed assets: | I12: Capital Expenditures | J12: Capex | K12: $0 | L12: No significant asset purchases beyond laptops (already in OpEx)
B13: Property & Equipment | C13: ='2-Income Statement'!D38-'2-Income Statement'!D68 -> 5200 | D13: ='2-Income Statement'!D38+'2-Income Statement'!E38-'2-Income Statement'!D68-'2-Income Statement'!E68 -> 5100 | E13: ='2-Income Statement'!D38+'2-Income Statement'!E38+'2-Income Statement'!F38-'2-Income Statement'!D68-'2-Income Statement'!E68-'2-Income Statement'!F68 -> 4700 | F13: ='2-Income Statement'!D38+'2-Income Statement'!E38+'2-Income Statement'!F38+'2-Income Statement'!G38-'2-Income Statement'!D68-'2-Income Statement'!E68-'2-Income Statement'!F68-'2-Income Statement'!G68 -> 4000 | G13: ='2-Income Statement'!D38+'2-Income Statement'!E38+'2-Income Statement'!F38+'2-Income Statement'!G38+'2-Income Statement'!H38-'2-Income Statement'!D68-'2-Income Statement'!E68-'2-Income Statement'!F68-'2-Income Statement'!G68-'2-Income Statement'!H68 -> 3000
B14: Total Assets | C14: =C11+C13 -> 379667.15 | D14: =D11+D13 -> 443464.29 | E14: =E11+E13 -> 937585.96 | F14: =F11+F13 -> 1904387.8 | G14: =G11+G13 -> 3555805.4
B16: Liabilities
B17: Accounts Payable | C17: =('2-Income Statement'!D49*30)/365 -> 2951.4616 | D17: =('2-Income Statement'!E49*30)/365 -> 6695.6041 | E17: =('2-Income Statement'!F49*30)/365 -> 10089.138 | F17: =('2-Income Statement'!G49*30)/365 -> 14403.572 | G17: =('2-Income Statement'!H49*30)/365 -> 19598.961
B18: Accrued expenses | C18: =('2-Income Statement'!D66*15)/365 -> 9994.837 | D18: =('2-Income Statement'!E66*15)/365 -> 12716.228 | E18: =('2-Income Statement'!F66*15)/365 -> 16833.34 | F18: =('2-Income Statement'!G66*15)/365 -> 22601.65 | G18: =('2-Income Statement'!H66*15)/365 -> 25557.346
B19: Total Liabilities | C19: =SUM(C17:C18) -> 12946.299 | D19: =SUM(D17:D18) -> 19411.832 | E19: =SUM(E17:E18) -> 26922.478 | F19: =SUM(F17:F18) -> 37005.222 | G19: =SUM(G17:G18) -> 45156.307
B21: Equity
B22: Equity Capital | C22: 500000 | D22: 500000 | E22: 500000 | F22: 500000 | G22: 500000
B23: Retained Earnings | C23: ='2-Income Statement'!D71 -> -133279.15 | D23: ='2-Income Statement'!E71+C23 -> -75947.543 | E23: ='2-Income Statement'!F71+D23 -> 410663.49 | F23: ='2-Income Statement'!G71+E23 -> 1367382.5 | G23: ='2-Income Statement'!H71+F23 -> 3010649.1
B24: Total Equity | C24: =SUM(C22:C23) -> 366720.85 | D24: =SUM(D22:D23) -> 424052.46 | E24: =SUM(E22:E23) -> 910663.49 | F24: =SUM(F22:F23) -> 1867382.5 | G24: =SUM(G22:G23) -> 3510649.1
B25: Total Liabilities & Equity | C25: =C19+C24 -> 379667.15 | D25: =D19+D24 -> 443464.29 | E25: =E19+E24 -> 937585.96 | F25: =F19+F24 -> 1904387.8 | G25: =G19+G24 -> 3555805.4
B27: Check | C27: =C14=C25 -> TRUE | D27: =D14=D25 -> TRUE | E27: =E14=E25 -> TRUE | F27: =F14=F25 -> TRUE | G27: =G14=G25 -> TRUE

Sheet 2-Income Statement
B2: WaveCare Forecast
D3: 2027 | E3: 2028 | F3: 2029 | G3: 2030 | H3: 2031
B4: Assumptions | C4: Unit | D4: Year 1 | E4: Year 2 | F4: Year 3 | G4: Year 4 | H4: Year 5 | J4: Note
B5: Market Base (by resident)
B6: Serviceable Available Market (SAM) | C6: # | D6: 49187 | E6: =INT(D6*1.02) -> 50170 | F6: =INT(E6*1.02) -> 51173 | G6: =INT(F6*1.02) -> 52196 | H6: =INT(G6*1.02) -> 53239 | J6: (1) Serviceable Available Market (SAM) is expected to increase by 2% each year.
B7: Adoption rate (Taiwanese market) | C7: % | D7: 0.007298 | E7: 0.02 | F7: 0.05 | G7: 0.08 | H7: 0.12
B8: Total residents | C8: # | D8: =INT(D6*D7) -> 358 | E8: =INT(E6*E7) -> 1003 | F8: =INT(F6*F7) -> 2558 | G8: =INT(G6*G7) -> 4175 | H8: =INT(H6*H7) -> 6388
B9: New residents | C9: # | D9: =D8 -> 358 | E9: =E8-D8 -> 645 | F9: =F8-E8 -> 1555 | G9: =G8-F8 -> 1617 | H9: =H8-G8 -> 2213
B10: Churn rate | C10: % | D10: 0 | E10: 0 | F10: 0.05 | G10: 0.05 | H10: 0.05
B11: Active residents | C11: # | D11: =INT(D8) -> 358 | E11: =INT(E8) -> 1003 | F11: =INT(F9+E11*(1-F10)) -> 2507 | G11: =INT(G9+F11*(1-G10)) -> 3998 | H11: =INT(H9+G11*(1-H10)) -> 6011
B12: Active facilities | C12: # | D12: =INT(D11/D13) -> 7 | E12: =INT(E11/E13) -> 20 | F12: =INT(F11/F13) -> 51 | G12: =INT(G11/G13) -> 81 | H12: =INT(H11/H13) -> 122
B13: Average residents in 1 facility | C13: # | D13: 49 | E13: 49 | F13: 49 | G13: 49 | H13: 49
B15: Revenue Assumptions
B16: Wristband
B17: Number of Sold Wristband | C17: # | D17: =D9 -> 358 | E17: =E9 -> 645 | F17: =F9 -> 1555 | G17: =G9 -> 1617 | H17: =H9 -> 2213
B18: Total Wristband Revenue | C18: $ | D18: =D9*99 -> 35442 | E18: =E9*99 -> 63855 | F18: =F9*99 -> 153945 | G18: =G9*99 -> 160083 | H18: =H9*99 -> 219087
B19: Gateway
B20: Number of Sold Gateway | C20: # | D20: =D9/10 -> 35.8 | E20: =E9/10 -> 64.5 | F20: =F9/10 -> 155.5 | G20: =G9/10 -> 161.7 | H20: =H9/10 -> 221.3
B21: Gateway Revenue | C21: $ | D21: =D9/10*325 -> 11635 | E21: =E9/10*325 -> 20962.5 | F21: =F9/10*325 -> 50537.5 | G21: =G9/10*325 -> 52552.5 | H21: =H9/10*325 -> 71922.5
B22: Total Hardware Revenue | C22: $ | D22: =D18+D21 -> 47077 | E22: =E18+E21 -> 84817.5 | F22: =F18+F21 -> 204482.5 | G22: =G18+G21 -> 212635.5 | H22: =H18+H21 -> 291009.5 | J22: (2) Wristband: US$ =99; Gateway: US$ =325$. Assumed that each 10 residents needs 1 Gateways. Installation Fee is included in the selling price.
B23: Annual Service
B24: Number of Active residents | C24: # | D24: =D11 -> 358 | E24: =E11 -> 1003 | F24: =F11 -> 2507 | G24: =G11 -> 3998 | H24: =H11 -> 6011
B25: Total Annual Service Revenue | C25: $ | D25: ='4-Monthly Service Revenue'!G20 -> 100061 | E25: ='4-Monthly Service Revenue'!G36 -> 365005.5 | F25: ='4-Monthly Service Revenue'!G52 -> 938043.74 | G25: ='4-Monthly Service Revenue'!G68 -> 1710680.3 | H25: ='4-Monthly Service Revenue'!G84 -> 2625923.2
B26: Total Revenue | C26: $ | D26: =D22+D25 -> 147138 | E26: =E22+E25 -> 449823 | F26: =F22+F25 -> 1142526.2 | G26: =G22+G25 -> 1923315.8 | H26: =H22+H25 -> 2916932.7
B28: Cost Structure
B29: Variable
B30: Wristband COGS | C30: $ | D30: =D9*43 -> 15394 | E30: =D30*103% -> 15855.82 | F30: =E30*103% -> 16331.495 | G30: =F30*103% -> 16821.439 | H30: =G30*103% -> 17326.083
B31: Gateway COSG | C31: $ | D31: =D9/10*102 -> 3651.6 | E31: =D31*103% -> 3761.148 | F31: =E31*103% -> 3873.9824 | G31: =F31*103% -> 3990.2019 | H31: =G31*103% -> 4109.908
B32: Total Hardware COSG | C32: $ | D32: =SUM(D30:D31) -> 19045.6 | E32: =D32*103% -> 19616.968 | F32: =E32*103% -> 20205.477 | G32: =F32*103% -> 20811.641 | H32: =G32*103% -> 21435.991 | J32: (3) Wristband cost: US$ = 43; Gateway cost: US$ = 102. Assume that the cost of the Hardware COSG is affected by 3% inflation every year.
B33: Installation Cost (per resident) | C33: $ | D33: =125*2/50 -> 5 | E33: =D33*103% -> 5.15 | F33: =E33*103% -> 5.3045 | G33: =F33*103% -> 5.463635 | H33: =G33*103% -> 5.6275441 | J33: (4) Assume that 2 temporary technicians can support installation & training for 50 residents/ day. Each person is paid US$125/ day. Assume that the cost of the Installation is affected by 3% inflation every year.
B34: Warranty Expense (variable portion) | C34: $ | D34: =D22*5% -> 2353.85 | E34: =D34*103% -> 2424.4655 | F34: =E34*103% -> 2497.1995 | G34: =F34*103% -> 2572.1154 | H34: =G34*103% -> 2649.2789 | J34: (5) Assume that 5% of Hardware Revenue is contributed to Warranty.
B35: Infrastructure cost (per resident) | C35: $ | D35: ='11-Infrastructure'!F2 -> 2.0111732 | E35: ='11-Infrastructure'!F3 -> 2.0937188 | F35: ='11-Infrastructure'!F4 -> 1.914639 | G35: ='11-Infrastructure'!F5 -> 1.9509755 | H35: ='11-Infrastructure'!F6 -> 2.4954251 | J35: (6) Infrastructure cost is on 9th Tab.
B36: Fixed
B37: Product R&D Cost | C37: $ | D37: 60000 | E37: =2%*E26 -> 8996.46 | F37: =2%*F26 -> 22850.525 | G37: =2%*G26 -> 38466.315 | H37: =2%*H26 -> 58338.653 | J37: (7) Coding cost is paid one-time to build Minimum Viable Product (MVP) at Y1. From Y2, 2% of Revenue is contributed to Product R&D.
B38: Certification & Compliance Cost | C38: $ | D38: 6500 | E38: 1500 | F38: 1500 | G38: 1500 | H38: 1500 | J38: (8) Spend US$6500 for NCC, RoHS, IP67 in Y1. For each year from Y2 to Y5, US$1500 is allocated for certificates. Assume that certificates are amortized in 5 years.
B39: Salaries & Commission | C39: $ | D39: ='5-Human Resource'!E30 -> 154707.7 | E39: ='5-Human Resource'!F30 -> 298281.75 | F39: ='5-Human Resource'!G30 -> 410928.25 | G39: ='5-Human Resource'!H30 -> 569683.05 | H39: ='5-Human Resource'!I30 -> 665170.17 | J39: (9) Assumptions are in Personel Sheet.
B40: Rent & Utilities | C40: $ | D40: =250*'5-Human Resource'!E16*12 -> 15000 | E40: =250*'5-Human Resource'!F16*12 -> 30000 | F40: =250*'5-Human Resource'!G16*12 -> 39000 | G40: =250*'5-Human Resource'!H16*12 -> 51000 | H40: =250*'5-Human Resource'!I16*12 -> 60000 | J40: (10) Assume that Co-working space/ Renting lab is US$250 per person per month. Utilities is included.
B41: Office supplies and Equipment | C41: $ | D41: =1500*'5-Human Resource'!E16+5000 -> 12500 | E41: =1500*('5-Human Resource'!F16-'5-Human Resource'!E16)+5000 -> 12500 | F41: =1500*('5-Human Resource'!G16-'5-Human Resource'!F16)+5000 -> 9500 | G41: =1500*('5-Human Resource'!H16-'5-Human Resource'!G16)+5000 -> 11000 | H41: =1500*('5-Human Resource'!I16-'5-Human Resource'!H16)+5000 -> 9500 | J41: (11) Assume that each employee needs 01 laptop (One-time: US$1500 per laptop) and annually US$5000 for other tools & equipments.
B42: Marketing & Campaigns | C42: $ | D42: 8000 | E42: =D42*105% -> 8400 | F42: =E42*105% -> 8820 | G42: =F42*105% -> 9261 | H42: =G42*105% -> 9724.05 | J42: (12) Marketing & Campaigns expenses for Taiwanese Market is spent on 2 main expos annually (Medical Taiwan - Jun & Care Expo Taipei - Sep). Each expo is expected to have US$ 4000. The budget for Taiwanese Market is raised 5% each year.
B43: Travel and Entertainment | C43: $ | D43: 5000 | E43: =D43*105% -> 5250 | F43: =E43*105% -> 5512.5 | G43: =F43*105% -> 5788.125 | H43: =G43*105% -> 6077.5312 | J43: (13) Travel and Entertainment is US$5000/ year. The budget is raised 5% each year.
...

Sheet 3-Cash Flow Statement
B2: WaveCare Forecast
B3: Pro-Forma Cash Flow Statement
C4: 2027 | D4: 2028 | E4: 2029 | F4: 2030 | G4: 2031
C5: Year 1 | D5: Year 2 | E5: Year 3 | F5: Year 4 | G5: Year 5 | I5: Note
B6: Operating Cash Flow
B7: Net Earnings | C7: ='2-Income Statement'!D71 -> -133279.15 | D7: ='2-Income Statement'!E71 -> 57331.607 | E7: ='2-Income Statement'!F71 -> 486611.03 | F7: ='2-Income Statement'!G71 -> 956719.05 | G7: ='2-Income Statement'!H71 -> 1643266.6
B8: Plus: Depreciation & Amortization | C8: ='2-Income Statement'!D68 -> 1300 | D8: ='2-Income Statement'!E68 -> 1600 | E8: ='2-Income Statement'!F68 -> 1900 | F8: ='2-Income Statement'!G68 -> 2200 | G8: ='2-Income Statement'!H68 -> 2500
B9: Less: Changes in Working Capital | C9: =-('1-Balance Sheet'!C9)-('1-Balance Sheet'!C10)+('1-Balance Sheet'!C17)+('1-Balance Sheet'!C18) -> -622.96644 | D9: =-('1-Balance Sheet'!D9-'1-Balance Sheet'!C9)-('1-Balance Sheet'!D10-'1-Balance Sheet'!C10)+('1-Balance Sheet'!D17-'1-Balance Sheet'!C17)+('1-Balance Sheet'!D18-'1-Balance Sheet'!C18) -> -20284.757 | E9: =-('1-Balance Sheet'!E9-'1-Balance Sheet'!D9)-('1-Balance Sheet'!E10-'1-Balance Sheet'!D10)+('1-Balance Sheet'!E17-'1-Balance Sheet'!D17)+('1-Balance Sheet'!E18-'1-Balance Sheet'!D18) -> -51120.634 | F9: =-('1-Balance Sheet'!F9-'1-Balance Sheet'!E9)-('1-Balance Sheet'!F10-'1-Balance Sheet'!E10)+('1-Balance Sheet'!F17-'1-Balance Sheet'!E17)+('1-Balance Sheet'!F18-'1-Balance Sheet'!E18) -> -56248.954 | G9: =-('1-Balance Sheet'!G9-'1-Balance Sheet'!F9)-('1-Balance Sheet'!G10-'1-Balance Sheet'!F10)+('1-Balance Sheet'!G17-'1-Balance Sheet'!F17)+('1-Balance Sheet'!G18-'1-Balance Sheet'!F18) -> -76113.753
B10: Cash from Operations | C10: =SUM(C7:C9) -> -132602.12 | D10: =SUM(D7:D9) -> 38646.849 | E10: =SUM(E7:E9) -> 437390.4 | F10: =SUM(F7:F9) -> 902670.1 | G10: =SUM(G7:G9) -> 1569652.8
B12: Investing Cash Flow
B13: Investments in Property & Equipment | C13: =-'2-Income Statement'!D38 -> -6500 | D13: =-'2-Income Statement'!E38 -> -1500 | E13: =-'2-Income Statement'!F38 -> -1500 | F13: =-'2-Income Statement'!G38 -> -1500 | G13: =-'2-Income Statement'!H38 -> -1500
B14: Cash from Investing | C14: =SUM(C13) -> -6500 | D14: =SUM(D13) -> -1500 | E14: =SUM(E13) -> -1500 | F14: =SUM(F13) -> -1500 | G14: =SUM(G13) -> -1500
B16: Financing Cash Flow
B17: Issuance (repayment) of debt | C17: 0 | D17: 0 | E17: 0 | F17: 0 | G17: 0
B18: Issuance (repayment) of equity | C18: 500000 | D18: 0 | E18: 0 | F18: 0 | G18: 0
B19: Cash from Financing | C19: =SUM(C17:C18) -> 500000 | D19: =SUM(D17:D18) -> 0 | E19: =SUM(E17:E18) -> 0 | F19: =SUM(F17:F18) -> 0 | G19: =SUM(G17:G18) -> 0
B21: Net Increase (decrease) in Cash | C21: =C10+C14+C19 -> 360897.88 | D21: =D10+D14+D19 -> 37146.849 | E21: =E10+E14+E19 -> 435890.4 | F21: =F10+F14+F19 -> 901170.1 | G21: =G10+G14+G19 -> 1568152.8
B22: Opening Cash Balance | C22: 0 | D22: =C23 -> 360897.88 | E22: =D23 -> 398044.73 | F22: =E23 -> 833935.13 | G22: =F23 -> 1735105.2
B23: Closing Cash Balance | C23: =SUM(C21:C22) -> 360897.88 | D23: =SUM(D21:D22) -> 398044.73 | E23: =SUM(E21:E22) -> 833935.13 | F23: =SUM(F21:F22) -> 1735105.2 | G23: =SUM(G21:G22) -> 3303258.1
B25: Free Cash Flow | C25: =C10+C14 -> -139102.12 | D25: =D10+D14 -> 37146.849 | E25: =E10+E14 -> 435890.4 | F25: =F10+F14 -> 901170.1 | G25: =G10+G14 -> 1568152.8

Sheet 4-Monthly Service Revenue
B2: WaveCare Monthly Service Revenue Cohort Assumption
B3: Assumptions | C3: Active from Y-1 | D3: New Signed | E3: Churn Rate | F3: Cumulative Total Active | G3: Monthly service revenue
B5: Taiwanese Market
B6: Year 1
B7: Month
B8: Jan | C8: 0 | D8: ='2-Income Statement'!$D$9/12 -> 29.833333 | E8: 0 | F8: =D8 -> 29.833333 | G8: =F8*43 -> 1282.8333 | I8: (1) Annual Service Fee is calculated based on 5% of Average Nursing Homes fee each month each patient (US$43/patient/month).
B9: Feb | C9: 0 | D9: ='2-Income Statement'!$D$9/12 -> 29.833333 | E9: 0 | F9: =C8+F8+D9 -> 59.666667 | G9: =F9*43 -> 2565.6667
B10: Mar | C10: 0 | D10: ='2-Income Statement'!$D$9/12 -> 29.833333 | E10: 0 | F10: =C9+F9+D10 -> 89.5 | G10: =F10*43 -> 3848.5
B11: Apr | C11: 0 | D11: ='2-Income Statement'!$D$9/12 -> 29.833333 | E11: 0 | F11: =C10+F10+D11 -> 119.33333 | G11: =F11*43 -> 5131.3333
B12: May | C12: 0 | D12: ='2-Income Statement'!$D$9/12 -> 29.833333 | E12: 0 | F12: =C11+F11+D12 -> 149.16667 | G12: =F12*43 -> 6414.1667
B13: Jun | C13: 0 | D13: ='2-Income Statement'!$D$9/12 -> 29.833333 | E13: 0 | F13: =C12+F12+D13 -> 179 | G13: =F13*43 -> 7697
B14: Jul | C14: 0 | D14: ='2-Income Statement'!$D$9/12 -> 29.833333 | E14: 0 | F14: =C13+F13+D14 -> 208.83333 | G14: =F14*43 -> 8979.8333
B15: Aug | C15: 0 | D15: ='2-Income Statement'!$D$9/12 -> 29.833333 | E15: 0 | F15: =C14+F14+D15 -> 238.66667 | G15: =F15*43 -> 10262.667
B16: Sep | C16: 0 | D16: ='2-Income Statement'!$D$9/12 -> 29.833333 | E16: 0 | F16: =C15+F15+D16 -> 268.5 | G16: =F16*43 -> 11545.5
B17: Oct | C17: 0 | D17: ='2-Income Statement'!$D$9/12 -> 29.833333 | E17: 0 | F17: =C16+F16+D17 -> 298.33333 | G17: =F17*43 -> 12828.333
B18: Nov | C18: 0 | D18: ='2-Income Statement'!$D$9/12 -> 29.833333 | E18: 0 | F18: =C17+F17+D18 -> 328.16667 | G18: =F18*43 -> 14111.167
B19: Dec | C19: 0 | D19: ='2-Income Statement'!$D$9/12 -> 29.833333 | E19: 0 | F19: =C18+F18+D19 -> 358 | G19: =F19*43 -> 15394
B20: Total Year 1 | D20: =SUM(D8:D19) -> 358 | F20: =F19 -> 358 | G20: =SUM(G8:G19) -> 100061
B22: Year 2
B23: Month
B24: Jan | C24: =$D$20 -> 358 | D24: ='2-Income Statement'!$E$9/12 -> 53.75 | E24: 0 | F24: =C24+D24 -> 411.75 | G24: =F24*43 -> 17705.25
B25: Feb | C25: =$D$20 -> 358 | D25: ='2-Income Statement'!$E$9/12 -> 53.75 | E25: 0 | F25: =F24+D25 -> 465.5 | G25: =F25*43 -> 20016.5
B26: Mar | C26: =$D$20 -> 358 | D26: ='2-Income Statement'!$E$9/12 -> 53.75 | E26: 0 | F26: =F25+D26 -> 519.25 | G26: =F26*43 -> 22327.75
B27: Apr | C27: =$D$20 -> 358 | D27: ='2-Income Statement'!$E$9/12 -> 53.75 | E27: 0 | F27: =F26+D27 -> 573 | G27: =F27*43 -> 24639
B28: May | C28: =$D$20 -> 358 | D28: ='2-Income Statement'!$E$9/12 -> 53.75 | E28: 0 | F28: =F27+D28 -> 626.75 | G28: =F28*43 -> 26950.25
B29: Jun | C29: =$D$20 -> 358 | D29: ='2-Income Statement'!$E$9/12 -> 53.75 | E29: 0 | F29: =F28+D29 -> 680.5 | G29: =F29*43 -> 29261.5
B30: Jul | C30: =$D$20 -> 358 | D30: ='2-Income Statement'!$E$9/12 -> 53.75 | E30: 0 | F30: =F29+D30 -> 734.25 | G30: =F30*43 -> 31572.75
B31: Aug | C31: =$D$20 -> 358 | D31: ='2-Income Statement'!$E$9/12 -> 53.75 | E31: 0 | F31: =F30+D31 -> 788 | G31: =F31*43 -> 33884
B32: Sep | C32: =$D$20 -> 358 | D32: ='2-Income Statement'!$E$9/12 -> 53.75 | E32: 0 | F32: =F31+D32 -> 841.75 | G32: =F32*43 -> 36195.25
B33: Oct | C33: =$D$20 -> 358 | D33: ='2-Income Statement'!$E$9/12 -> 53.75 | E33: 0 | F33: =F32+D33 -> 895.5 | G33: =F33*43 -> 38506.5
B34: Nov | C34: =$D$20 -> 358 | D34: ='2-Income Statement'!$E$9/12 -> 53.75 | E34: 0 | F34: =F33+D34 -> 949.25 | G34: =F34*43 -> 40817.75
B35: Dec | C35: =$D$20 -> 358 | D35: ='2-Income Statement'!$E$9/12 -> 53.75 | E35: 0 | F35: =F34+D35 -> 1003 | G35: =F35*43 -> 43129
B36: Total Year 2 | D36: =SUM(D24:D35) -> 645 | F36: =F35 -> 1003 | G36: =SUM(G24:G35) -> 365005.5
B38: Year 3
B39: Month
B40: Jan | C40: =$F$36 -> 1003 | D40: ='2-Income Statement'!$F$9/12 -> 129.58333 | E40: =(1-'2-Income Statement'!$F$10)^(1/12)-1 -> -0.0042653188 | F40: =C40+D40+C40*E40 -> 1128.3052 | G40: =F40*43 -> 48517.124
B41: Feb | C41: =C40+C40*E40 -> 998.72189 | D41: ='2-Income Statement'!$F$9/12 -> 129.58333 | E41: =(1-'2-Income Statement'!$F$10)^(1/12)-1 -> -0.0042653188 | F41: =F40+D41+C41*E41 -> 1253.6287 | G41: =F41*43 -> 53906.033
B42: Mar | C42: =C41+C41*E41 -> 994.46202 | D42: ='2-Income Statement'!$F$9/12 -> 129.58333 | E42: =(1-'2-Income Statement'!$F$10)^(1/12)-1 -> -0.0042653188 | F42: =F41+D42+C42*E42 -> 1378.9703 | G42: =F42*43 -> 59295.724
B43: Apr | C43: =C42+C42*E42 -> 990.22032 | D43: ='2-Income Statement'!$F$9/12 -> 129.58333 | E43: =(1-'2-Income Statement'!$F$10)^(1/12)-1 -> -0.0042653188 | F43: =F42+D43+C43*E43 -> 1504.33 | G43: =F43*43 -> 64686.192
B44: May | C44: =C43+C43*E43 -> 985.99672 | D44: ='2-Income Statement'!$F$9/12 -> 129.58333 | E44: =(1-'2-Income Statement'!$F$10)^(1/12)-1 -> -0.0042653188 | F44: =F43+D44+C44*E44 -> 1629.7078 | G44: =F44*43 -> 70077.435
...

Sheet 5-Human Resource
B2: WaveCare Personel Forecast
E3: 2027 | F3: 2028 | G3: 2029 | H3: 2030 | I3: 2031
B4: Assumptions | C4: Unit | D4: Base Salary | E4: Year 1 | F4: Year 2 | G4: Year 3 | H4: Year 4 | I4: Year 5 | K4: Note
B5: Quantity Assumptions
B6: Engineer
B7: Firmware Engineer | C7: # | E7: 1 | F7: 1 | G7: 1 | H7: 1 | I7: 1
B8: Backend Engineer | C8: # | E8: 1 | F8: 2 | G8: 3 | H8: 4 | I8: 4
B9: AI Engineer | C9: # | E9: 1 | F9: 1 | G9: 1 | H9: 2 | I9: 2
B10: Field Application Engineer (FAE) | C10: # | E10: 0 | F10: 1 | G10: 2 | H10: 3 | I10: 4
B11: Mobile Developer | C11: # | E11: 0 | F11: 1 | G11: 1 | H11: 1 | I11: 1
B12: Business Development
B13: Business Development Employee (Taiwanese Market) | C13: # | E13: 1 | F13: 2 | G13: 3 | H13: 3 | I13: 4 | K13: (1) Commission is based on 5% revenue of the Hardware.
B14: Admin/ Support
B15: Customer Support Employee (Taiwanese Market) | C15: # | E15: 1 | F15: 2 | G15: 2 | H15: 3 | I15: 4
B16: Total | C16: # | E16: =SUM(E7:E15) -> 5 | F16: =SUM(F7:F15) -> 10 | G16: =SUM(G7:G15) -> 13 | H16: =SUM(H7:H15) -> 17 | I16: =SUM(I7:I15) -> 20
B17: Salaries
B18: Engineer
B19: Firmware Engineer ($3000 per month) | C19: $ | D19: 3000 | E19: =D19*E7*12 -> 36000 | F19: =E19*105%/E7*F7 -> 37800 | G19: =F19*105%/F7*G7 -> 39690 | H19: =G19*105%/G7*H7 -> 41674.5 | I19: =H19*105%/H7*I7 -> 43758.225 | K19: (2) Assume that Salary Increase Rate is 5% annually.
B20: Backend Engineer ($3000 per month) | C20: $ | D20: 3000 | E20: =D20*E8*12 -> 36000 | F20: =E20*105%/E8*F8 -> 75600 | G20: =F20*105%/F8*G8 -> 119070 | H20: =G20*105%/G8*H8 -> 166698 | I20: =H20*105%/H8*I8 -> 175032.9
B21: AI Engineer ($4000 per month) | C21: $ | D21: 4000 | E21: =D21*E9*12 -> 48000 | F21: =E21*105%/E9*F9 -> 50400 | G21: =F21*105%/F9*G9 -> 52920 | H21: =G21*105%/G9*H9 -> 111132 | I21: =H21*105%/H9*I9 -> 116688.6
B22: Field Application Engineer ($2500 per month) | C22: $ | D22: 2500 | E22: =D22*E10*12 -> 0 | F22: =F10*D22*12 -> 30000 | G22: =F22*105%/F10*G10 -> 63000 | H22: =G22*105%/G10*H10 -> 99225 | I22: =H22*105%/H10*I10 -> 138915
B23: Mobile Developer | C23: $ | D23: 3000 | E23: =E11*D23*12 -> 0 | F23: =F11*D23*12 -> 36000 | G23: =F23*105%/F11*G11 -> 37800 | H23: =G23*105%/G11*H11 -> 39690 | I23: =H23*105%/H11*I11 -> 41674.5
B24: Business Development
B25: Business Development Employee ($1500 per month) | C25: $ | D25: 1500 | E25: =D25*SUM(E13:E13)*12 -> 18000 | F25: =$D$25*12*SUM(F13:F13) -> 36000 | G25: =$D$25*12*SUM(G13:G13) -> 54000 | H25: =$D$25*12*SUM(H13:H13) -> 54000 | I25: =$D$25*12*SUM(I13:I13) -> 72000
B26: Business Development Employee's Commission | C26: $ | E26: =10%*'2-Income Statement'!D22 -> 4707.7 | F26: =10%*'2-Income Statement'!E22 -> 8481.75 | G26: =10%*'2-Income Statement'!F22 -> 20448.25 | H26: =10%*'2-Income Statement'!G22 -> 21263.55 | I26: =10%*'2-Income Statement'!H22 -> 29100.95 | K26: (3) Assume that Commission is based on 10% of the Hardware Revenue.
B27: Total | E27: =SUM(E25:E26) -> 22707.7 | F27: =SUM(F25:F26) -> 44481.75 | G27: =SUM(G25:G26) -> 74448.25 | H27: =SUM(H25:H26) -> 75263.55 | I27: =SUM(I25:I26) -> 101100.95
B28: Admin/ Support
B29: Customer Support Employee ($1000 per month) | C29: $ | D29: 1000 | E29: =$D$29*SUM(E15:E15)*12 -> 12000 | F29: =$D$29*SUM(F15:F15)*12 -> 24000 | G29: =$D$29*SUM(G15:G15)*12 -> 24000 | H29: =$D$29*SUM(H15:H15)*12 -> 36000 | I29: =$D$29*SUM(I15:I15)*12 -> 48000
B30: Total Salaries | C30: $ | E30: =E19+E20+E21+E22+E27+E29+E23 -> 154707.7 | F30: =F19+F20+F21+F22+F27+F29+F23 -> 298281.75 | G30: =G19+G20+G21+G22+G27+G29+G23 -> 410928.25 | H30: =H19+H20+H21+H22+H27+H29+H23 -> 569683.05 | I30: =I19+I20+I21+I22+I27+I29+I23 -> 665170.17

Sheet 6-BD Scaling 
B2: Year | C2: BD | D2: Expected new residents | E2: AVG residents in 1 facility | F2: Close rate | G2: Expected Lead/BD/Year | H2: New Sales (by facility)
B3: Taiwanese Market
B4: Y1 | C4: 2 | D4: ='2-Income Statement'!D9 -> 358 | E4: 49 | F4: 0.15 | G4: =D4/E4/F4/C4 -> 24.353741 | H4: =G4*F4*C4 -> 7.3061224
B5: Y2 | C5: 3 | D5: ='2-Income Statement'!E9 -> 645 | E5: 49 | F5: 0.2 | G5: =D5/E5/F5/C5 -> 21.938776 | H5: =G5*F5*C5 -> 13.163265
B6: Y3 | C6: 4 | D6: ='2-Income Statement'!F9 -> 1555 | E6: 49 | F6: 0.22 | G6: =D6/E6/F6/C6 -> 36.062152 | H6: =G6*F6*C6 -> 31.734694
B7: Y4 | C7: 4 | D7: ='2-Income Statement'!G9 -> 1617 | E7: 49 | F7: 0.23 | G7: =D7/E7/F7/C7 -> 35.869565 | H7: =G7*F7*C7 -> 33
B8: Y5 | C8: 5 | D8: ='2-Income Statement'!H9 -> 2213 | E8: 49 | F8: 0.25 | G8: =D8/E8/F8/C8 -> 36.130612 | H8: =G8*F8*C8 -> 45.163265
B9: Total | H9: =SUM(H4:H8) -> 130.36735

Sheet 7-NPV, IRR, TV
B2: Year | C2: CF | D2: WACC | E2: Discount Factor | F2: NPV
B3: 0 | C3: =-500000 -> -500000 | D3: 0.2 | E3: =1/(1+D3)^B3 -> 1 | F3: =C3*E3 -> -500000
B4: 1 | C4: ='3-Cash Flow Statement'!C25 -> -139102.12 | D4: 0.2 | E4: =1/(1+D4)^B4 -> 0.83333333 | F4: =C4*E4 -> -115918.43
B5: 2 | C5: ='3-Cash Flow Statement'!D25 -> 37146.849 | D5: 0.2 | E5: =1/(1+D5)^B5 -> 0.69444444 | F5: =C5*E5 -> 25796.423
B6: 3 | C6: ='3-Cash Flow Statement'!E25 -> 435890.4 | D6: 0.2 | E6: =1/(1+D6)^B6 -> 0.5787037 | F6: =C6*E6 -> 252251.39
B7: 4 | C7: ='3-Cash Flow Statement'!F25 -> 901170.1 | D7: 0.2 | E7: =1/(1+D7)^B7 -> 0.48225309 | F7: =C7*E7 -> 434592.06
B8: 5 | C8: ='3-Cash Flow Statement'!G25 -> 1568152.8 | D8: 0.2 | E8: =1/(1+D8)^B8 -> 0.40187757 | F8: =C8*E8 -> 630205.45
B9: Total NPV | F9: =SUM(F3:F8) -> 726926.9
B11: IRR (no TV) | C11: =IRR(C3:C8) -> 0.45808929
B13: TV | C13: =C8*(1+2%)/(20%-2%) -> 8886199.4 | E13: g (assume that growth) = 2%
B14: PV(TV) | C14: =C13/(1+20%)^5 -> 3571164.2

Sheet 8-Reference
A1: Nursing Institute Report | B1: https://nurse.mohw.gov.tw/mp-2.html
A2: Elderly Instution Report | B2: https://stis.mohw.gov.tw/HWSDweb/common/CommonQuery.aspx?code=G&id=69&utm_source=chatgpt.com
A3: Benchmark for prices | B3: https://www.ncoa.org/product-resources/medical-alert-systems/best-medical-alert-systems-with-fall-detection/?utm_source=chatgpt.com
A4: Nursing homes price/month | B4: https://www.aftygh.gov.tw/english-dep/nursing-home/?utm_source=chatgpt.com https://chnh.mohw.gov.tw/eng/content/index.aspx?Parser=1%2C14%2C95%2C79&utm_source=chatgpt.com https://www.tsmh.org.tw/sites/tsmhcare/fee.html?utm_source=chatgpt.com https://www.paochien.com.tw/twuse/page?pageid=1100005&typeid=1000&utm_source=chatgpt.com https://wwwv.tsgh.ndmutsgh.edu.tw/unit/10071/17981
A5: Nurse call band | B5: https://store.directsupply.com/Product/replacement-wristband-transmitter-tl-4005-door-systems-11023710?quantity=1
A6: Japanese Market
A7: Korean Market | B7: https://www.jkgn.org/journal/view.php?number=619&utm_source=chatgpt.com
A8: Japanese Market | B8: https://www.mhlw.go.jp/toukei/saikin/hw/kaigo/service24/dl/gaikyo.pdf?utm_source=chatgpt.com
A9: Questions | B9: Financial | C9: Is the market too small? Should we expand to other countries? From what year?
C10: NPV too small?
C11: Warranty = 5% too small or not?
C12: R&D 2% is too small or not?
C13: Do we have to make the balance sheet & cashflow ?
C14: 400k Funding is enough or not?
C15: Should we include salary of C-Level?
C16: WACC 20% ?
B17: Validation | C17: What if we haven't gotten any KPI?
A20: Lawsuits | B20: https://news.ltn.com.tw/news/Kaohsiung/breakingnews/3964990

Sheet 9-Customer List
A1: Name | B1: Number of Nurses (Nursing staff only,excluding care workers) | C1: Number of Residents | D1: How much residents pay for 1 month
A2: 大稻埕護理之家 | B2: 6 | C2: 24 beds | D2: $36,000~$50,000
A3: 新北市私立清福護理之家 | B3: 10 | C3: 97 beds | D3: $40,000
A4: 佛教慈濟醫療財團法人附設台中慈濟護理之家 | B4: 58 | C4: 450 beds | D4: $25,200~$49,600
A5: 承恩護理之家 | B5: 7 | C5: 47 beds | D5: $35,000~$50,000
A6: 員林郭醫院附設護理之家 | B6: 10 | C6: 135 beds | D6: $31,000~$37,000
A7: 松群護理之家 | B7: 7 | C7: 79 beds | D7: $32,000
A8: 重建樂活護理之家 | B8: 6 | C8: 22 beds | D8: $42,000
A9: 光田護理之家 | B9: 12 | C9: 130 beds | D9: $33,000~$50,000
A10: 八里同仁護理之家 | B10: 5 | C10: 44 beds | D10: $36,000~$54,000
A11: 長宸護理之家 | B11: 5 | C11: 45 beds | D11: $42,000~$46,000
A12: 松慈護理之家 | B12: 13 | C12: 99 beds | D12: $21,000
A13: 世華護理之家 | B13: 5 | C13: 40 beds | D13: $16,800~$29,000
... A52: 長庚醫療財團法人附設長青護理之家 | B52: 39 | C52: 310 beds | D52: $35,000~$72,000
A53: 長庚養生文化村 | B53: N/A | C53: 400 rooms | D53: $27,500~$47,800
A54: 潤福生活新象 | B54: N/A | C54: 300 rooms | D54: $27,850
A55: 康寧養生會館 | B55: N/A | C55: 165 rooms | D55: $72,000~$138,000
A56: 陽明老人公寓 | B56: N/A | C56: 85 | D56: $16,800~$25,400
A57: Zhi-Shan Senior Home (by Cardinal Tien Memorial Hospital of Yungho) | B57: N/A | C57: 109 | D57: $23,600
A59: 1st year pilot
A60: Name | B60: Beds | C60: AVG Monthly Fee
A61: 長庚養生文化村 | B61: 400 | C61: 37.65
A62: 潤福生活新象 | B62: 300 | C62: 27.85
A63: 康寧養生會館 (Replaced for being an outlier) | B63: 165 | C63: 25,725 (Median)
A64: 陽明老人公寓 | B64: 85 | C64: 21.1
A65: Zhi-Shan Senior Home | B65: 109 | C65: 23.6
A66: Total | B66: 1.059 | C66: 135.925
A67: AVG | B67: 212 | C67: 27.185
A69: Year | B69: Expected population (>65yo) (in millions) | C69: % population
A70: 2026 | B70: 4.86 | C70: 20.8%
A71: 2027 | B71: 5 | C71: 21.3%
A72: 2028 | B72: 5.13 | C72: 21.7%
A73: 2029 | B73: 5.30 | C73: 22.2%
A74: 2030 | B74: 5.57 | C74: 24.2%
A75: 2031 | B75: 5.70 | C75: 24.8%

Sheet 10-Bill of Material (Hardware)
A1: Wristband BOM (per unit) – Total $43
A2: Component | B2: Description / Function | C2: Cost (USD)
A3: MCU + Zigbee | B3: Integrated SoC (e.g., CC2652) for processing & Zigbee communication | C3: $6.00
A4: IMU | B4: 6‑axis accelerometer + gyroscope (motion, posture) | C4: $3.00
A5: PPG Sensor | B5: Heart rate & SpO₂ monitoring (e.g., MAX30102) | C5: $4.00
A6: Temperature Sensor | B6: Skin temperature measurement | C6: $1.00
A7: GSR Sensor | B7: Galvanic skin response (stress / emotional state) | C7: $1.00
A8: Rechargeable Battery | B8: Lithium‑polymer, 100–200 mAh | C8: $3.00
A9: Flex‑wave Module | B9: Indoor ambient light harvesting (hybrid charging) | C9: $5.00
A10: PCB + Assembly | B10: Board fabrication, SMT assembly | C10: $8.00
A11: Casing + Strap | B11: Medical‑grade plastic, skin‑friendly strap | C11: $5.00
A12: QA & Testing | B12: Functional testing, IP67 waterproof calibration | C12: $4.00
A13: Packaging | B13: Box, manual, charging cable (backup) | C13: $3.00
A14: Total | C14: $43.00
A16: Gateway BOM (per unit) – Total $102
A17: Component | B17: Description / Function | C17: Cost (USD)
A18: Raspberry Pi 5 (4GB) | B18: Main processor for edge AI, data fusion, local alerting | C18: $60.00
A19: Zigbee USB Dongle | B19: Zigbee coordinator (e.g., SONOFF CC2652P) | C19: $15.00
A20: MicroSD Card (32GB) | B20: OS + local database storage | C20: $7.00
A21: Power Supply | B21: 5V/3A USB‑C adapter | C21: $10.00
A22: Case + Heatsink | B22: Protective enclosure, cooling | C22: $10.00
A23: Total | C23: $102.00

Sheet 11-Infrastructure
A1: Year | B1: Active Residents | C1: Cloud + GAI Cost (USD/month) | D1: AVG (month) | E1: AVG (yearly) | F1: AVG cost/ resident (yearly) | H1: 1. Compute (Application Backend & APIs)
A2: 2027 | B2: 358 | C2: 50–70 | D2: 60 | E2: =D2*12 -> 720 | F2: =E2/B2 -> 2.0111732 | H2: Item | I2: Description | J2: Typical Pricing (AWS/GCP/Azure)
A3: 2028 | B3: 1003 | C3: 150–200 | D3: 175 | E3: =D3*12 -> 2100 | F3: =E3/B3 -> 2.0937188 | H3: Virtual machines (EC2 / Compute Engine) | I3: Hosting API server, dashboard backend, data processing | J3: Starting from ~$8–15/month for t3.micro (1 vCPU, 1GB RAM) after free tier
A4: 2029 | B4: 2507 | C4: 300–500 | D4: 400 | E4: =D4*12 -> 4800 | F4: =E4/B4 -> 1.914639 | H4: Auto‑scaling group (optional) | I4: For handling traffic spikes | J4: Additional cost based on instance hours
A5: 2030 | B5: 3998 | C5: 500–800 | D5: 650 | E5: =D5*12 -> 7800 | F5: =E5/B5 -> 1.9509755 | H5: Load balancer (ALB / CLB) | I5: Distribute traffic across backend instances | J5: ~18–25/month+18–25/month+0.008 per GB processed
A6: 2031 | B6: 6011 | C6: 1,000–1,500 | D6: 1250 | E6: =D6*12 -> 15000 | F6: =E6/B6 -> 2.4954251 | H6: 2. Database & Storage
H7: Item | I7: Description | J7: Typical Pricing
A8: Key Assumptions | H8: Relational database (PostgreSQL) | I8: Store user accounts, facilities, alerts, configurations | J8: ~$15–30/month for db.t3.micro; scales with storage
A9: Year | B9: Phase | C9: Infrastructure & Cost Drivers | H9: Time‑series database (InfluxDB / Timestream) | I9: Store vital signs (HR, SpO₂, temperature, motion) | J9: Free tier available; paid ~$0.50–1.00 per million writes. Self‑hosted InfluxDB OSS is free.
A10: 2027 | B10: Pilot | C10: Mostly AWS/GCP free tier; minimal LLM inference (chatbot trial) | H10: Object storage (S3 / GCS) | I10: Store logs, ML models, reports, backups | J10: ~$0.023/GB per month; minimal cost for pilot
A11: 2028 | B11: Early expansion | C11: IoT Core beyond free tier; RDS t3.small; chatbot active for 2–3 facilities | H11: Backup & archival (Glacier / Coldline) | I11: Long‑term backup of critical data | J11: ~$0.004/GB per month
A12: 2029 | B12: Growth | C12: Production RDS (t3.medium); API Gateway + CloudFront; moderate LLM usage | H12: 3. IoT & Messaging
A13: 2030 | B13: Large expansion | C13: Aurora Serverless or larger RDS; GPU spot for LLM; NAT Gateway, backup | H13: Item | I13: Description | J13: Typical Pricing
A14: 2031 | B14: Full scale | C14: Production cluster (Aurora PostgreSQL); load balancer; significant LLM inference | H14: IoT message broker (AWS IoT Core / MQTT) | I14: Receive data from gateways | J14: Free tier: 250k messages/month (12 months). After: ~$1 per million messages
H15: NAT Gateway | I15: Allow private instances to access internet (e.g., for updates) | J15: ~0.045/hour+dataprocessing( 0.045/hour+dataprocessing( 45/month) – optional for pilot
H16: 4. API & Web Delivery
H17: Item | I17: Description | J17: Typical Pricing
H18: API Gateway | I18: Expose REST/HTTP API for web/mobile apps | J18: Free tier: 1M requests/month. After: ~$1–3.50 per million requests (HTTP vs REST)
H19: CDN (CloudFront / Cloud CDN) | I19: Deliver dashboard static assets (images, JS, CSS) | J19: ~$0.085/GB for data transfer; free tier available
H20: 5. Generative AI (GAI) – LLM Inference
H21: Item | I21: Description | J21: Typical Pricing (as of 2025)
H22: LLM API calls (token‑based) | I22: Chatbot answers nurse questions | J22: GPT‑4o mini: 0.15/1Minputtokens,0.15/1Minputtokens,0.60 / 1M output tokens.
J23: Claude 3 Haiku: ~0.25/1Minput,0.25/1Minput,1.25 / 1M output.
J24: GPT‑5‑nano (Azure): 0.05/0.05/0.40
H25: Prompt caching (if supported) | I25: Reduces cost for repeated context | J25: Azure GPT‑5: input tokens reduce from 1.25to1.25to0.125 / 1M
H26: GPU instances for fine‑tuning | I26: Train or fine‑tune models with proprietary data | J26: ~$0.50–1.00 per hour (spot instance) for g4dn.xlarge (T4 GPU)
H27: Vector database (optional) | I27: For retrieval‑augmented generation (RAG) | J27: Pinecone / Milvus Cloud: starting ~$75/month for small scale. Self‑hosted is free.
H28: 6. Monitoring, Logging & Management
H29: Item | I29: Description | J29: Typical Pricing
H30: Cloud logging (CloudWatch / Stackdriver) | I30: Aggregate logs from services | J30: ~$0.50/GB ingested; first 5GB may be free
H31: Metrics & alerts | I31: Monitor API uptime, error rates, resource usage | J31: Usually included in basic monitoring
H32: Tracing (e.g., AWS X‑Ray) | I32: Debug performance bottlenecks | J32: ~$0.00002 per trace (very low for pilot)
H33: 7. Development & One‑Time Costs (not monthly)
H34: Item | I34: Description | J34: Estimated Cost (one‑time)
H35: GAI MVP (chatbot + RAG + basic dashboard) | I35: Build conversational AI for nurse queries | J35: 20,000–20,000–40,000
H36: Production GAI (staffing optimization, automated reporting, deep integration) | I36: Advanced labor‑saving features | J36: 50,000–50,000–100,000
H37: Backend + API development | I37: Nurse dashboard, mobile app backend | J37: 15,000–15,000–25,000 (in‑house or outsourced)
H38: MLOps pipeline setup | I38: Model versioning, inference logging, retraining triggers | J38: 3,000–3,000–5,000
